#VRML_SIM R2023b utf8

EXTERNPROTO "https://raw.githubusercontent.com/cyberbotics/webots/R2023b/projects/objects/trees/protos/BigSassafras.proto"
EXTERNPROTO "https://raw.githubusercontent.com/cyberbotics/webots/R2023b/projects/objects/trees/protos/Cypress.proto"
EXTERNPROTO "https://raw.githubusercontent.com/cyberbotics/webots/R2023b/projects/appearances/protos/DryMud.proto"
EXTERNPROTO "https://raw.githubusercontent.com/cyberbotics/webots/R2023b/projects/objects/trees/protos/Oak.proto"
EXTERNPROTO "https://raw.githubusercontent.com/cyberbotics/webots/R2023b/projects/appearances/protos/PaintedWood.proto"
EXTERNPROTO "https://raw.githubusercontent.com/cyberbotics/webots/R2023b/projects/objects/trees/protos/Pine.proto"
EXTERNPROTO "https://raw.githubusercontent.com/cyberbotics/webots/R2023b/projects/appearances/protos/Rubber.proto"
EXTERNPROTO "https://raw.githubusercontent.com/cyberbotics/webots/R2023b/projects/objects/trees/protos/SimpleTree.proto"
EXTERNPROTO "https://raw.githubusercontent.com/cyberbotics/webots/R2023b/projects/objects/backgrounds/protos/TexturedBackground.proto"
EXTERNPROTO "https://raw.githubusercontent.com/cyberbotics/webots/R2023b/projects/objects/backgrounds/protos/TexturedBackgroundLight.proto"
EXTERNPROTO "https://raw.githubusercontent.com/cyberbotics/webots/R2023b/projects/objects/floors/protos/UnevenTerrain.proto"

WorldInfo {
}
Viewpoint {
  orientation 0.5209493205889114 -0.22109354037710477 -0.8244570648502378 3.814765403151161
  position 37.0802522050564 -9.086756489800367 101.75308518084164
}
TexturedBackground {
}
TexturedBackgroundLight {
}
Robot {
  translation -23.45457474768514 19.79792684320919 3.9132280869551472
  rotation 0.07432608284264401 -0.015049963134077981 0.9971204200190322 -1.5774640241754758
  children [
    DEF Solid Solid {
      translation 0 -1.26 0.55
      children [
        Camera {
          translation -17013.40303836593 25588.632699566482 -284068.7465177624
          rotation -0.013843088616965284 -0.05144618984022011 0.9985798207697105 3.1415852531332433
          children [
            Shape {
              appearance PBRAppearance {
              }
              geometry Box {
                size 0.1 0.1 0.1
              }
            }
          ]
          physics Physics {
            mass 1
          }
          linearVelocity 0 0 -2367.5846400003065
        }
        DEF cam_stand Shape {
          appearance PBRAppearance {
            baseColor 0.3 0.3 0.3
          }
          geometry Box {
            size 0.3 0.3 0.1
          }
        }
      ]
      name "Solid"
    }
    DEF base Shape {
      appearance PaintedWood {
        colorOverride 0 0.2 0.1
      }
      geometry DEF Base Box {
        size 1.2 3 1
      }
    }
    DistanceSensor {
      translation 0.35 -1.5 0
      rotation 0 0 1 -1.5707853071795865
      children [
        DEF ds Shape {
          appearance PBRAppearance {
            baseColor 1 1 0
            metalness 0
          }
          geometry Sphere {
            radius 0.1
          }
        }
      ]
      name "ds_right"
      boundingObject DEF ds Shape {
        appearance PBRAppearance {
          baseColor 1 1 0
          metalness 0
        }
        geometry Sphere {
          radius 0.1
        }
      }
      physics DEF phy2 Physics {
        mass 1
      }
      lookupTable [
        0 0 0
        3 1000 0
      ]
      numberOfRays 2
    }
    DistanceSensor {
      translation -0.35 -1.5 0
      rotation 0 0 -1 1.57079
      children [
        DEF ds Shape {
          appearance PBRAppearance {
            baseColor 1 1 0
            metalness 0
          }
          geometry Sphere {
            radius 0.1
          }
        }
      ]
      name "ds_left"
      lookupTable [
        0 0 0
        3 1000 0
      ]
      numberOfRays 2
    }
    DEF wheel1 HingeJoint {
      jointParameters HingeJointParameters {
        position 3319.318656575783
        anchor 0.75 -0.96 -0.53
      }
      device [
        RotationalMotor {
          name "wheel1"
          maxTorque 50
        }
      ]
      endPoint Solid {
        translation 0.7499990499236211 -0.9599846527818492 -0.5300031463566605
        rotation -0.6161719480915151 -0.4905691056313874 -0.6161769899835013 4.053733494650947
        children [
          DEF wheel Shape {
            appearance Rubber {
            }
            geometry Cylinder {
              height 0.5
              radius 0.5
            }
          }
        ]
        boundingObject USE wheel
        physics DEF phy1 Physics {
          mass 1
        }
        linearVelocity 6.830291463515726e-05 0.0001498717401815699 4.191652994895638e-05
        angularVelocity -0.004438015391245923 -3.992821394837066 0.23819573247471268
      }
    }
    DEF wheel2 HingeJoint {
      jointParameters HingeJointParameters {
        position -1148.1486131898732
        anchor -0.75 -0.96 -0.53
      }
      device [
        RotationalMotor {
          name "wheel2"
          maxTorque 50
        }
      ]
      endPoint Solid {
        translation -0.7499985356674741 -0.9600123785133667 -0.529979844128857
        rotation 0.59625887242033 0.5375381875458842 0.5962617327901586 2.15516080560138
        children [
          DEF wheel Shape {
            appearance Rubber {
            }
            geometry Cylinder {
              height 0.5
              radius 0.5
            }
          }
        ]
        name "solid(1)"
        boundingObject USE wheel
        physics USE phy1
        linearVelocity -9.19093712293706e-05 0.00013785815578443663 -0.00016323847566213946
        angularVelocity -0.0045028588537208165 -3.992945765787824 0.23825495231163113
      }
    }
    DEF wheel3 HingeJoint {
      jointParameters HingeJointParameters {
        position 3303.198411011081
        anchor 0.75 0.96 -0.53
      }
      device [
        RotationalMotor {
          name "wheel3"
          maxTorque 50
        }
      ]
      endPoint Solid {
        translation 0.750001387583962 0.9599773751245456 -0.5299942466469437
        rotation -0.6099877706915098 0.5057826363487665 -0.6099990527655706 2.2050792085834043
        children [
          DEF wheel Shape {
            appearance Rubber {
            }
            geometry Cylinder {
              height 0.5
              radius 0.5
            }
          }
        ]
        name "solid(2)"
        boundingObject USE wheel
        physics USE phy1
        linearVelocity 1.4298419097147404e-05 0.0001932793876639399 -1.2195530759260892e-05
        angularVelocity -0.004468871427961244 -3.9929156058960733 0.2382095728052999
      }
    }
    DEF wheel4 HingeJoint {
      jointParameters HingeJointParameters {
        position -1156.495815598706
        anchor -0.75 0.96 -0.53
      }
      device [
        RotationalMotor {
          name "wheel4"
          maxTorque 50
        }
      ]
      endPoint Solid {
        translation -0.7500009508139986 0.9599993948532296 -0.5299843449243272
        rotation -0.1900950207104128 0.9631857298578974 -0.19009769304022922 1.6083053308232533
        children [
          DEF wheel Shape {
            appearance Rubber {
            }
            geometry Cylinder {
              height 0.5
              radius 0.5
            }
          }
        ]
        name "solid(3)"
        boundingObject USE wheel
        physics USE phy1
        linearVelocity -5.671759610642579e-05 0.0001925331218900985 -2.5645551185012853e-05
        angularVelocity -0.0045611485950564044 -3.9928376700719395 0.23829606640316636
      }
    }
  ]
  boundingObject USE base
  physics USE phy1
  controller "forest_controller"
  linearVelocity 1.5380962140625343e-06 0.0001897569427110284 -4.951760926309135e-05
  angularVelocity -7.316889155615586e-05 -4.8188731734556126e-05 3.379055987955904e-05
}
DEF forest Solid {
  children [
    Pine {
      translation -15.62 20.85 1.15
      name "pine tree(6)"
    }
    Pine {
      translation -15.62 -10.45 1.15
      name "pine tree(5)"
    }
    Pine {
      translation 11.67 -10.45 1.45
      name "pine tree(3)"
    }
    Pine {
      translation 20.49 -10.45 2.81
      name "pine tree(4)"
    }
    Pine {
      translation 11.67 15.84 1.88
      name "pine tree(2)"
    }
    Pine {
      translation -4.35 9.25 2.22
      name "pine tree(1)"
    }
    Pine {
      translation -4.35 -3.53 2.18
    }
    SimpleTree {
      translation 0 0 3
    }
    SimpleTree {
      translation 6 0 3
      name "tree(1)"
    }
    SimpleTree {
      translation 6 10 3
      name "tree(2)"
    }
    SimpleTree {
      translation 16 15 3
      name "tree(3)"
    }
    SimpleTree {
      translation -16 -15 1.8
      name "tree(4)"
    }
    SimpleTree {
      translation 16 -15 3
      name "tree(5)"
    }
    SimpleTree {
      translation 5 -22 2
      name "tree(6)"
    }
    SimpleTree {
      translation -15 -22 2
      name "tree(7)"
    }
    SimpleTree {
      translation -9 22 2
      name "tree(8)"
    }
    SimpleTree {
      translation -18 16 2.5
      name "tree(9)"
    }
    SimpleTree {
      translation -22 -3 2
      name "tree(10)"
    }
    SimpleTree {
      translation 10 -8 3
      name "tree(11)"
    }
    SimpleTree {
      translation -5 -8 2.3
      name "tree(12)"
    }
    SimpleTree {
      translation 1 -17 2
      name "tree(13)"
    }
    Oak {
      translation 14.94 0 3.24
    }
    Oak {
      translation 20 -5.97 3.28
      name "oak tree(1)"
    }
    Oak {
      translation 15.97 -10.75 3.02
      name "oak tree(2)"
    }
    Oak {
      translation 15.97 11.04 3.07
      name "oak tree(3)"
    }
    Oak {
      translation -24.52 6.27 2.46
      name "oak tree(4)"
    }
    Oak {
      translation -12.06 2.39 2.09
      name "oak tree(6)"
    }
    Oak {
      translation -13.84 10.96 2.09
      name "oak tree(7)"
    }
    Oak {
      translation -2.97 18.97 1.79
      name "oak tree(8)"
    }
    Oak {
      translation 0.35 13.07 2.24
      name "oak tree(9)"
    }
    Oak {
      translation -9.22 15.64 2.72
      name "oak tree(5)"
    }
    Oak {
      translation 7.46 20.45 2.43
      name "oak tree(10)"
    }
    Oak {
      translation 16.74 21.4 2.43
      name "oak tree(11)"
    }
    BigSassafras {
      translation -11.82 -13.71 1.72
    }
    BigSassafras {
      translation -21.32 -8.95 1.72
      name "sassafras tree(1)"
    }
    BigSassafras {
      translation 19.67 7.95 3.44
      name "sassafras tree(2)"
    }
    BigSassafras {
      translation 19.67 -1.13 2.97
      name "sassafras tree(3)"
    }
    BigSassafras {
      translation 21.66 -19.93 2.97
      name "sassafras tree(4)"
    }
    BigSassafras {
      translation 9.84 -19.93 2.64
      name "sassafras tree(5)"
    }
    BigSassafras {
      translation -6.69 -19.93 1.29
      name "sassafras tree(6)"
    }
    BigSassafras {
      translation -16.82 -5.16 2.98
      name "sassafras tree(7)"
    }
    BigSassafras {
      translation -16.82 8.12 2.98
      name "sassafras tree(8)"
    }
    BigSassafras {
      translation -21.82 21.14 2.98
      name "sassafras tree(9)"
    }
    BigSassafras {
      translation 1.95 21.14 2.63
      name "sassafras tree(10)"
    }
    Cypress {
      translation -11.36 0 1.96
    }
    Cypress {
      translation -14.16 5.78 2.06
      name "cypress tree(1)"
    }
    Cypress {
      translation 20.42 15.8 3.01
      name "cypress tree(2)"
    }
    Cypress {
      translation 21.87 20.79 3.01
      name "cypress tree(3)"
    }
    Cypress {
      translation 11.51 1.81 3.01
      name "cypress tree(4)"
    }
    Cypress {
      translation 2.77 -10.75 2.51
      name "cypress tree(5)"
    }
    Cypress {
      translation -2.24 -21.57 1.87
      name "cypress tree(6)"
    }
    Cypress {
      translation 15.22 -21.57 2.5
      name "cypress tree(7)"
    }
    Cypress {
      translation 6.61 -15.53 2.8
      name "cypress tree(8)"
    }
    Cypress {
      translation -11.26 5.51 2.26
      name "cypress tree(9)"
    }
  ]
}
UnevenTerrain {
}
DEF Border Solid {
  translation 0 0 3.9
  children [
    Solid {
      translation -1.3792605043011323e-07 -25.200000625478946 -0.37012555483941023
      rotation -0.030209004771724574 -0.10649179531902823 0.99385457364769 1.1643902338565348e-05
      children [
        DEF border Shape {
          appearance DryMud {
          }
          geometry Box {
            size 49 1 3
          }
        }
      ]
      name "border1"
      boundingObject USE border
      physics DEF phy1 Physics {
        mass 1
      }
      linearVelocity 0 0 -1.2139209860606136e-07
    }
    Solid {
      translation 0 25.53 -0.3701254747645879
      children [
        DEF border Shape {
          appearance DryMud {
          }
          geometry Box {
            size 49 1 3
          }
        }
      ]
      name "border2"
      boundingObject USE border
      physics USE phy1
      linearVelocity 0 0 -1.2139209860606136e-07
    }
    Solid {
      translation 25.53 0 -0.37
      rotation 0 0 1 1.5708
      children [
        DEF border Shape {
          appearance DryMud {
          }
          geometry Box {
            size 49 1 3
          }
        }
      ]
      name "border3"
      boundingObject USE border
    }
    Solid {
      translation -25.53017847354663 4.209898174571635e-05 -0.37012479565948864
      rotation 3.0016706219414937e-05 -0.00011636421087890974 0.9999999927791839 1.571353921869714
      children [
        DEF border Shape {
          appearance DryMud {
          }
          geometry Box {
            size 49 1 3
          }
        }
      ]
      name "border4"
      boundingObject USE border
      physics USE phy1
      linearVelocity 6.816077529947506e-09 -5.238600397206028e-08 -2.218740451667145e-07
      angularVelocity -4.18645314375363e-06 1.136832187590803e-07 -1.4871030269110154e-07
    }
  ]
  name "solid(1)"
}
